Workbook
Name Slicer_branch: #N/A
Name Slicer_Months: #N/A
Name Slicer_name: #N/A
Name Slicer_reason_for_visit: #N/A
Name Slicer_speialization: #N/A

Sheet Raw-data
A1: appointment_id | B1: patient_id | C1: doctor_id | D1: appointment_date | E1: appointment_time | F1: reason_for_visit | G1: status | J1: patient_id | K1: first_name | L1: last_name | M1: gender | N1: date_of_birth | O1: contact_number | P1: address | Q1: registration_date | R1: insurance_provider | S1: insurance_number | T1: email | W1: doctor_id | X1: first_name | Y1: last_name | Z1: specialization | AA1: phone_number | AB1: years_experience | AC1: hospital_branch | AD1: email
A2: A001 | B2: P034 | C2: D009 | D2: 45147 | E2: 0.63541667 | F2: Therapy | G2: Scheduled | J2: P001 | K2: David | L2: Williams | M2: F | N2: 20244 | O2: 6939585183 | P2: 789 Pine Rd | Q2: 44735 | R2: WellnessCorp | S2: INS840674 | T2: david.williams@mail.com | W2: D001 | X2: David | Y2: Taylor | Z2: Dermatology | AA2: 8322010158 | AB2: 17 | AC2: Westside Clinic | AD2: dr.david.taylor@hospital.com
A3: A002 | B3: P032 | C3: D004 | D3: 45086 | E3: 0.60416667 | F3: Therapy | G3: No-show | J3: P002 | K3: Emily | L3: Smith | M3: F | N3: 30967 | O3: 8228188767 | P3: 321 Maple Dr | Q3: 44576 | R3: PulseSecure | S3: INS354079 | T3: emily.smith@mail.com | W3: D002 | X3: Jane | Y3: Davis | Z3: Pediatrics | AA3: 9004382050 | AB3: 24 | AC3: Eastside Clinic | AD3: dr.jane.davis@hospital.com
A4: A003 | B4: P048 | C4: D004 | D4: 45105 | E4: 0.33333333 | F4: Consultation | G4: Cancelled | J4: P003 | K4: Laura | L4: Jones | M4: M | N4: 28358 | O4: 8397029847 | P4: 321 Maple Dr | Q4: 44599 | R4: PulseSecure | S4: INS650929 | T4: laura.jones@mail.com | W4: D003 | X4: Jane | Y4: Smith | Z4: Pediatrics | AA4: 8737740598 | AB4: 19 | AC4: Eastside Clinic | AD4: dr.jane.smith@hospital.com
A5: A004 | B5: P025 | C5: D006 | D5: 45170 | E5: 0.38541667 | F5: Consultation | G5: Cancelled | J5: P004 | K5: Michael | L5: Johnson | M5: F | N5: 29637 | O5: 9019443432 | P5: 123 Elm St | Q5: 44257 | R5: HealthIndia | S5: INS789944 | T5: michael.johnson@mail.com | W5: D004 | X5: David | Y5: Jones | Z5: Pediatrics | AA5: 6594221991 | AB5: 28 | AC5: Central Hospital | AD5: dr.david.jones@hospital.com
A6: A005 | B6: P040 | C6: D003 | D6: 45113 | E6: 0.53125 | F6: Emergency | G6: No-show | J6: P005 | K6: David | L6: Wilson | M6: M | N6: 22090 | O6: 7734463155 | P6: 123 Elm St | Q6: 44468 | R6: MedCare Plus | S6: INS788105 | T6: david.wilson@mail.com | W6: D005 | X6: Sarah | Y6: Taylor | Z6: Dermatology | AA6: 9118538547 | AB6: 26 | AC6: Central Hospital | AD6: dr.sarah.taylor@hospital.com
A7: A006 | B7: P045 | C7: D006 | D7: 45096 | E7: 0.67708333 | F7: Checkup | G7: Scheduled | J7: P006 | K7: Linda | L7: Jones | M7: M | N7: 23178 | O7: 7561777264 | P7: 321 Maple Dr | Q7: 44836 | R7: HealthIndia | S7: INS613758 | T7: linda.jones@mail.com | W7: D006 | X7: Alex | Y7: Davis | Z7: Pediatrics | AA7: 6570137231 | AB7: 23 | AC7: Central Hospital | AD7: dr.alex.davis@hospital.com
A8: A007 | B8: P001 | C8: D007 | D8: 45025 | E8: 0.4375 | F8: Consultation | G8: Scheduled | J8: P007 | K8: Alex | L8: Johnson | M8: F | N8: 32667 | O8: 6278710077 | P8: 789 Pine Rd | Q8: 44555 | R8: MedCare Plus | S8: INS465890 | T8: alex.johnson@mail.com | W8: D007 | X8: Robert | Y8: Davis | Z8: Oncology | AA8: 8217493115 | AB8: 26 | AC8: Westside Clinic | AD8: dr.robert.davis@hospital.com
A9: A008 | B9: P016 | C9: D010 | D9: 45070 | E9: 0.36458333 | F9: Consultation | G9: Cancelled | J9: P008 | K9: David | L9: Davis | M9: F | N9: 27946 | O9: 7090558393 | P9: 456 Oak Ave | Q9: 44341 | R9: WellnessCorp | S9: INS545101 | T9: david.davis@mail.com | W9: D008 | X9: Linda | Y9: Brown | Z9: Dermatology | AA9: 9069162601 | AB9: 5 | AC9: Westside Clinic | AD9: dr.linda.brown@hospital.com
A10: A009 | B10: P039 | C10: D010 | D10: 44990 | E10: 0.57291667 | F10: Follow-up | G10: Scheduled | J10: P009 | K10: Laura | L10: Davis | M10: M | N10: 26278 | O10: 7060324619 | P10: 321 Maple Dr | Q10: 44822 | R10: PulseSecure | S10: INS136631 | T10: laura.davis@mail.com | W10: D009 | X10: Sarah | Y10: Smith | Z10: Pediatrics | AA10: 7387087517 | AB10: 26 | AC10: Central Hospital | AD10: dr.sarah.smith@hospital.com
A11: A010 | B11: P005 | C11: D003 | D11: 44939 | E11: 0.64583333 | F11: Therapy | G11: Completed | J11: P010 | K11: Michael | L11: Taylor | M11: M | N11: 37177 | O11: 7081396733 | P11: 123 Elm St | Q11: 44797 | R11: WellnessCorp | S11: INS866577 | T11: michael.taylor@mail.com | W11: D010 | X11: Linda | Y11: Wilson | Z11: Oncology | AA11: 6176383634 | AB11: 21 | AC11: Eastside Clinic | AD11: dr.linda.wilson@hospital.com
A12: A011 | B12: P022 | C12: D007 | D12: 45242 | E12: 0.66666667 | F12: Checkup | G12: No-show | J12: P011 | K12: Emily | L12: Jones | M12: F | N12: 24445 | O12: 8990604070 | P12: 789 Pine Rd | Q12: 44831 | R12: MedCare Plus | S12: INS172991 | T12: emily.jones@mail.com
A13: A012 | B13: P029 | C13: D003 | D13: 45053 | E13: 0.41666667 | F13: Follow-up | G13: Completed | J13: P012 | K13: Laura | L13: Davis | M13: F | N13: 33580 | O13: 8135666049 | P13: 321 Maple Dr | Q13: 45043 | R13: MedCare Plus | S13: INS104014 | T13: laura.davis@mail.com
A14: A013 | B14: P003 | C14: D002 | D14: 45154 | E14: 0.5 | F14: Emergency | G14: Scheduled | J14: P013 | K14: Laura | L14: Johnson | M14: F | N14: 32960 | O14: 9059178882 | P14: 321 Maple Dr | Q14: 44553 | R14: WellnessCorp | S14: INS373237 | T14: laura.johnson@mail.com
A15: A014 | B15: P012 | C15: D010 | D15: 45071 | E15: 0.4375 | F15: Emergency | G15: Cancelled | J15: P014 | K15: Alex | L15: Taylor | M15: M | N15: 24895 | O15: 7292262512 | P15: 789 Pine Rd | Q15: 45272 | R15: MedCare Plus | S15: INS118070 | T15: alex.taylor@mail.com
A16: A015 | B16: P026 | C16: D004 | D16: 44941 | E16: 0.71875 | F16: Consultation | G16: No-show | J16: P015 | K16: Sarah | L16: Johnson | M16: M | N16: 23508 | O16: 6636028516 | P16: 321 Maple Dr | Q16: 44464 | R16: WellnessCorp | S16: INS922209 | T16: sarah.johnson@mail.com
A17: A016 | B17: P016 | C17: D008 | D17: 45107 | E17: 0.45833333 | F17: Consultation | G17: Scheduled | J17: P016 | K17: Michael | L17: Taylor | M17: M | N17: 36729 | O17: 7223380592 | P17: 789 Pine Rd | Q17: 44400 | R17: PulseSecure | S17: INS156958 | T17: michael.taylor@mail.com
A18: A017 | B18: P037 | C18: D009 | D18: 45118 | E18: 0.70833333 | F18: Emergency | G18: Scheduled | J18: P017 | K18: Jane | L18: Jones | M18: M | N18: 33359 | O18: 6158428240 | P18: 456 Oak Ave | Q18: 44830 | R18: WellnessCorp | S18: INS182074 | T18: jane.jones@mail.com
A19: A018 | B19: P022 | C19: D007 | D19: 45244 | E19: 0.40625 | F19: Consultation | G19: Cancelled | J19: P018 | K19: Laura | L19: Wilson | M19: M | N19: 29122 | O19: 7145815738 | P19: 789 Pine Rd | Q19: 44827 | R19: PulseSecure | S19: INS635017 | T19: laura.wilson@mail.com
A20: A019 | B20: P029 | C20: D001 | D20: 44963 | E20: 0.64583333 | F20: Checkup | G20: Cancelled | J20: P019 | K20: Sarah | L20: Miller | M20: M | N20: 27538 | O20: 8618058864 | P20: 789 Pine Rd | Q20: 45101 | R20: WellnessCorp | S20: INS855073 | T20: sarah.miller@mail.com
A21: A020 | B21: P014 | C21: D003 | D21: 45265 | E21: 0.63541667 | F21: Consultation | G21: Completed | J21: P020 | K21: Jane | L21: Moore | M21: F | N21: 37778 | O21: 8158989953 | P21: 789 Pine Rd | Q21: 44654 | R21: MedCare Plus | S21: INS276089 | T21: jane.moore@mail.com
A22: A021 | B22: P028 | C22: D009 | D22: 45040 | E22: 0.41666667 | F22: Therapy | G22: No-show | J22: P021 | K22: Michael | L22: Wilson | M22: M | N22: 37316 | O22: 7765390555 | P22: 321 Maple Dr | Q22: 44580 | R22: WellnessCorp | S22: INS297392 | T22: michael.wilson@mail.com
A23: A022 | B23: P005 | C23: D001 | D23: 45244 | E23: 0.54166667 | F23: Consultation | G23: No-show | J23: P022 | K23: John | L23: Brown | M23: M | N23: 20219 | O23: 6221099573 | P23: 321 Maple Dr | Q23: 44327 | R23: MedCare Plus | S23: INS258823 | T23: john.brown@mail.com
... A51: A050 | B51: P045 | C51: D008 | D51: 45154 | E51: 0.625 | F51: Consultation | G51: No-show | J51: P050 | K51: Laura | L51: Wilson | M51: M | N51: 34330 | O51: 8301134730 | P51: 321 Maple Dr | Q51: 45044 | R51: WellnessCorp | S51: INS712210 | T51: laura.wilson@mail.com
A52: A051 | B52: P004 | C52: D006 | D52: 44961 | E52: 0.48958333 | F52: Checkup | G52: Completed
A53: A052 | B53: P016 | C53: D008 | D53: 45119 | E53: 0.39583333 | F53: Therapy | G53: No-show
A54: A053 | B54: P024 | C54: D005 | D54: 44969 | E54: 0.4375 | F54: Checkup | G54: Cancelled
A55: A054 | B55: P016 | C55: D008 | D55: 45276 | E55: 0.48958333 | F55: Follow-up | G55: Scheduled
A56: A055 | B56: P002 | C56: D010 | D56: 45205 | E56: 0.72916667 | F56: Checkup | G56: Scheduled
A57: A056 | B57: P049 | C57: D004 | D57: 44928 | E57: 0.53125 | F57: Checkup | G57: Scheduled
A58: A057 | B58: P028 | C58: D010 | D58: 45031 | E58: 0.73958333 | F58: Emergency | G58: Completed
A59: A058 | B59: P032 | C59: D008 | D59: 45055 | E59: 0.55208333 | F59: Consultation | G59: No-show
A60: A059 | B60: P027 | C60: D010 | D60: 44994 | E60: 0.64583333 | F60: Therapy | G60: Cancelled
A61: A060 | B61: P020 | C61: D002 | D61: 45252 | E61: 0.71875 | F61: Checkup | G61: No-show
A62: A061 | B62: P024 | C62: D005 | D62: 44941 | E62: 0.70833333 | F62: Therapy | G62: No-show
A63: A062 | B63: P012 | C63: D009 | D63: 45091 | E63: 0.63541667 | F63: Checkup | G63: No-show
... A201: A200 | B201: P007 | C201: D005 | D201: 45290 | E201: 0.42708333 | F201: Consultation | G201: Cancelled

Sheet cleaned data
A1: appointment_id | B1: appointment_date | C1: appointment_time | D1: reason_for_visit | E1: status | F1: patient_id | G1: Patient name | H1: Gender | I1: date of birth | J1: Age Group | K1: Group | L1: doctor_id | M1: Doctor name | N1: speialization | O1: years of experience | P1: hospital | Q1: branch | CL1: doctor_id | CM1: first_name | CN1: last_name | CO1: specialization | CP1: phone_number | CQ1: years_experience | CR1: hospital | CS1: Branch | CT1: email | CU1: Name | CX1: patient_id | CY1: first_name | CZ1: last_name | DA1: gender | DB1: date_of_birth | DC1: contact_number | DD1: address | DE1: registration_date | DF1: insurance_provider | DG1: insurance_number | DH1: email | DI1: name
A2: A016 | B2: 45107 | C2: 0.45833333 | D2: Consultation | E2: Scheduled | F2: P016 | G2: =VLOOKUP(F2,$CX$1:$DI$51,12,FALSE) -> Michael Taylor | H2: =VLOOKUP(F2,$CX$1:$DI$51,4,FALSE) -> M | I2: =VLOOKUP(F2,$CX$1:$DI$51,5,FALSE) -> 36729 | J2: =DATEDIF(I2,TODAY(),"Y") -> 26 | K2: =_xlfn.IFS(J2<=18,"0-18 Group",J2<=30,"19-30 Group",J2<=45,"31-45 Group",J2<=60,"46-60 Group",J2>60,"60+ ") -> 19-30 Group | L2: D008 | M2: =VLOOKUP(L2,$CL$1:$CU$11,10,FALSE) -> Linda Brown | N2: =VLOOKUP(L2,$CL$1:$CU$11,4,FALSE) -> Dermatology | O2: =VLOOKUP(L2,$CL$1:$CU$11,6,FALSE) -> 5 | P2: =VLOOKUP(L2,$CL$1:$CU$11,7,FALSE) -> Westside | Q2: =VLOOKUP(L2,$CL$1:$CU$11,8,FALSE) -> Clinic | CL2: D001 | CM2: David | CN2: Taylor | CO2: Dermatology | CP2: 8322010158 | CQ2: 17 | CR2: Westside | CS2: Clinic | CT2: dr.david.taylor@hospital.com | CU2: =CM2&" "&CN2 -> David Taylor | CX2: P001 | CY2: David | CZ2: Williams | DA2: F | DB2: 20244 | DC2: 6939585183 | DD2: 789 Pine Rd | DE2: 44735 | DF2: WellnessCorp | DG2: INS840674 | DH2: david.williams@mail.com | DI2: =CY2&" "&CZ2 -> David Williams
A3: A024 | B3: 45098 | C3: 0.33333333 | D3: Checkup | E3: Completed | F3: P049 | G3: =VLOOKUP(F3,$CX$1:$DI$51,12,FALSE) -> David Moore | H3: =VLOOKUP(F3,$CX$1:$DI$51,4,FALSE) -> M | I3: =VLOOKUP(F3,$CX$1:$DI$51,5,FALSE) -> 26629 | J3: =DATEDIF(I3,TODAY(),"Y") -> 53 | K3: =_xlfn.IFS(J3<=18,"0-18 Group",J3<=30,"19-30 Group",J3<=45,"31-45 Group",J3<=60,"46-60 Group",J3>60,"60+ ") -> 46-60 Group | L3: D008 | M3: =VLOOKUP(L3,$CL$1:$CU$11,10,FALSE) -> Linda Brown | N3: =VLOOKUP(L3,$CL$1:$CU$11,4,FALSE) -> Dermatology | O3: =VLOOKUP(L3,$CL$1:$CU$11,6,FALSE) -> 5 | P3: =VLOOKUP(L3,$CL$1:$CU$11,7,FALSE) -> Westside | Q3: =VLOOKUP(L3,$CL$1:$CU$11,8,FALSE) -> Clinic | CL3: D002 | CM3: Jane | CN3: Davis | CO3: Pediatrics | CP3: 9004382050 | CQ3: 24 | CR3: Eastside | CS3: Clinic | CT3: dr.jane.davis@hospital.com | CU3: =CM3&" "&CN3 -> Jane Davis | CX3: P002 | CY3: Emily | CZ3: Smith | DA3: F | DB3: 30967 | DC3: 8228188767 | DD3: 321 Maple Dr | DE3: 44576 | DF3: PulseSecure | DG3: INS354079 | DH3: emily.smith@mail.com | DI3: =CY3&" "&CZ3 -> Emily Smith
A4: A050 | B4: 45154 | C4: 0.625 | D4: Consultation | E4: No-show | F4: P045 | G4: =VLOOKUP(F4,$CX$1:$DI$51,12,FALSE) -> Linda Miller | H4: =VLOOKUP(F4,$CX$1:$DI$51,4,FALSE) -> F | I4: =VLOOKUP(F4,$CX$1:$DI$51,5,FALSE) -> 24222 | J4: =DATEDIF(I4,TODAY(),"Y") -> 60 | K4: =_xlfn.IFS(J4<=18,"0-18 Group",J4<=30,"19-30 Group",J4<=45,"31-45 Group",J4<=60,"46-60 Group",J4>60,"60+ ") -> 46-60 Group | L4: D008 | M4: =VLOOKUP(L4,$CL$1:$CU$11,10,FALSE) -> Linda Brown | N4: =VLOOKUP(L4,$CL$1:$CU$11,4,FALSE) -> Dermatology | O4: =VLOOKUP(L4,$CL$1:$CU$11,6,FALSE) -> 5 | P4: =VLOOKUP(L4,$CL$1:$CU$11,7,FALSE) -> Westside | Q4: =VLOOKUP(L4,$CL$1:$CU$11,8,FALSE) -> Clinic | CL4: D003 | CM4: Jane | CN4: Smith | CO4: Pediatrics | CP4: 8737740598 | CQ4: 19 | CR4: Eastside | CS4: Clinic | CT4: dr.jane.smith@hospital.com | CU4: =CM4&" "&CN4 -> Jane Smith | CX4: P003 | CY4: Laura | CZ4: Jones | DA4: M | DB4: 28358 | DC4: 8397029847 | DD4: 321 Maple Dr | DE4: 44599 | DF4: PulseSecure | DG4: INS650929 | DH4: laura.jones@mail.com | DI4: =CY4&" "&CZ4 -> Laura Jones
A5: A052 | B5: 45119 | C5: 0.39583333 | D5: Therapy | E5: No-show | F5: P016 | G5: =VLOOKUP(F5,$CX$1:$DI$51,12,FALSE) -> Michael Taylor | H5: =VLOOKUP(F5,$CX$1:$DI$51,4,FALSE) -> M | I5: =VLOOKUP(F5,$CX$1:$DI$51,5,FALSE) -> 36729 | J5: =DATEDIF(I5,TODAY(),"Y") -> 26 | K5: =_xlfn.IFS(J5<=18,"0-18 Group",J5<=30,"19-30 Group",J5<=45,"31-45 Group",J5<=60,"46-60 Group",J5>60,"60+ ") -> 19-30 Group | L5: D008 | M5: =VLOOKUP(L5,$CL$1:$CU$11,10,FALSE) -> Linda Brown | N5: =VLOOKUP(L5,$CL$1:$CU$11,4,FALSE) -> Dermatology | O5: =VLOOKUP(L5,$CL$1:$CU$11,6,FALSE) -> 5 | P5: =VLOOKUP(L5,$CL$1:$CU$11,7,FALSE) -> Westside | Q5: =VLOOKUP(L5,$CL$1:$CU$11,8,FALSE) -> Clinic | CL5: D004 | CM5: David | CN5: Jones | CO5: Pediatrics | CP5: 6594221991 | CQ5: 28 | CR5: Central | CS5: Hospital | CT5: dr.david.jones@hospital.com | CU5: =CM5&" "&CN5 -> David Jones | CX5: P004 | CY5: Michael | CZ5: Johnson | DA5: F | DB5: 29637 | DC5: 9019443432 | DD5: 123 Elm St | DE5: 44257 | DF5: HealthIndia | DG5: INS789944 | DH5: michael.johnson@mail.com | DI5: =CY5&" "&CZ5 -> Michael Johnson
A6: A054 | B6: 45276 | C6: 0.48958333 | D6: Follow-up | E6: Scheduled | F6: P016 | G6: =VLOOKUP(F6,$CX$1:$DI$51,12,FALSE) -> Michael Taylor | H6: =VLOOKUP(F6,$CX$1:$DI$51,4,FALSE) -> M | I6: =VLOOKUP(F6,$CX$1:$DI$51,5,FALSE) -> 36729 | J6: =DATEDIF(I6,TODAY(),"Y") -> 26 | K6: =_xlfn.IFS(J6<=18,"0-18 Group",J6<=30,"19-30 Group",J6<=45,"31-45 Group",J6<=60,"46-60 Group",J6>60,"60+ ") -> 19-30 Group | L6: D008 | M6: =VLOOKUP(L6,$CL$1:$CU$11,10,FALSE) -> Linda Brown | N6: =VLOOKUP(L6,$CL$1:$CU$11,4,FALSE) -> Dermatology | O6: =VLOOKUP(L6,$CL$1:$CU$11,6,FALSE) -> 5 | P6: =VLOOKUP(L6,$CL$1:$CU$11,7,FALSE) -> Westside | Q6: =VLOOKUP(L6,$CL$1:$CU$11,8,FALSE) -> Clinic | CL6: D005 | CM6: Sarah | CN6: Taylor | CO6: Dermatology | CP6: 9118538547 | CQ6: 26 | CR6: Central | CS6: Hospital | CT6: dr.sarah.taylor@hospital.com | CU6: =CM6&" "&CN6 -> Sarah Taylor | CX6: P005 | CY6: David | CZ6: Wilson | DA6: M | DB6: 22090 | DC6: 7734463155 | DD6: 123 Elm St | DE6: 44468 | DF6: MedCare Plus | DG6: INS788105 | DH6: david.wilson@mail.com | DI6: =CY6&" "&CZ6 -> David Wilson
A7: A058 | B7: 45055 | C7: 0.55208333 | D7: Consultation | E7: No-show | F7: P032 | G7: =VLOOKUP(F7,$CX$1:$DI$51,12,FALSE) -> Alex Moore | H7: =VLOOKUP(F7,$CX$1:$DI$51,4,FALSE) -> M | I7: =VLOOKUP(F7,$CX$1:$DI$51,5,FALSE) -> 29594 | J7: =DATEDIF(I7,TODAY(),"Y") -> 45 | K7: =_xlfn.IFS(J7<=18,"0-18 Group",J7<=30,"19-30 Group",J7<=45,"31-45 Group",J7<=60,"46-60 Group",J7>60,"60+ ") -> 31-45 Group | L7: D008 | M7: =VLOOKUP(L7,$CL$1:$CU$11,10,FALSE) -> Linda Brown | N7: =VLOOKUP(L7,$CL$1:$CU$11,4,FALSE) -> Dermatology | O7: =VLOOKUP(L7,$CL$1:$CU$11,6,FALSE) -> 5 | P7: =VLOOKUP(L7,$CL$1:$CU$11,7,FALSE) -> Westside | Q7: =VLOOKUP(L7,$CL$1:$CU$11,8,FALSE) -> Clinic | CL7: D006 | CM7: Alex | CN7: Davis | CO7: Pediatrics | CP7: 6570137231 | CQ7: 23 | CR7: Central | CS7: Hospital | CT7: dr.alex.davis@hospital.com | CU7: =CM7&" "&CN7 -> Alex Davis | CX7: P006 | CY7: Linda | CZ7: Jones | DA7: M | DB7: 23178 | DC7: 7561777264 | DD7: 321 Maple Dr | DE7: 44836 | DF7: HealthIndia | DG7: INS613758 | DH7: linda.jones@mail.com | DI7: =CY7&" "&CZ7 -> Linda Jones
A8: A078 | B8: 45186 | C8: 0.46875 | D8: Consultation | E8: No-show | F8: P013 | G8: =VLOOKUP(F8,$CX$1:$DI$51,12,FALSE) -> Laura Johnson | H8: =VLOOKUP(F8,$CX$1:$DI$51,4,FALSE) -> F | I8: =VLOOKUP(F8,$CX$1:$DI$51,5,FALSE) -> 32960 | J8: =DATEDIF(I8,TODAY(),"Y") -> 36 | K8: =_xlfn.IFS(J8<=18,"0-18 Group",J8<=30,"19-30 Group",J8<=45,"31-45 Group",J8<=60,"46-60 Group",J8>60,"60+ ") -> 31-45 Group | L8: D008 | M8: =VLOOKUP(L8,$CL$1:$CU$11,10,FALSE) -> Linda Brown | N8: =VLOOKUP(L8,$CL$1:$CU$11,4,FALSE) -> Dermatology | O8: =VLOOKUP(L8,$CL$1:$CU$11,6,FALSE) -> 5 | P8: =VLOOKUP(L8,$CL$1:$CU$11,7,FALSE) -> Westside | Q8: =VLOOKUP(L8,$CL$1:$CU$11,8,FALSE) -> Clinic | CL8: D007 | CM8: Robert | CN8: Davis | CO8: Oncology | CP8: 8217493115 | CQ8: 26 | CR8: Westside | CS8: Clinic | CT8: dr.robert.davis@hospital.com | CU8: =CM8&" "&CN8 -> Robert Davis | CX8: P007 | CY8: Alex | CZ8: Johnson | DA8: F | DB8: 32667 | DC8: 6278710077 | DD8: 789 Pine Rd | DE8: 44555 | DF8: MedCare Plus | DG8: INS465890 | DH8: alex.johnson@mail.com | DI8: =CY8&" "&CZ8 -> Alex Johnson
A9: A082 | B9: 44946 | C9: 0.44791667 | D9: Follow-up | E9: Scheduled | F9: P002 | G9: =VLOOKUP(F9,$CX$1:$DI$51,12,FALSE) -> Emily Smith | H9: =VLOOKUP(F9,$CX$1:$DI$51,4,FALSE) -> F | I9: =VLOOKUP(F9,$CX$1:$DI$51,5,FALSE) -> 30967 | J9: =DATEDIF(I9,TODAY(),"Y") -> 41 | K9: =_xlfn.IFS(J9<=18,"0-18 Group",J9<=30,"19-30 Group",J9<=45,"31-45 Group",J9<=60,"46-60 Group",J9>60,"60+ ") -> 31-45 Group | L9: D008 | M9: =VLOOKUP(L9,$CL$1:$CU$11,10,FALSE) -> Linda Brown | N9: =VLOOKUP(L9,$CL$1:$CU$11,4,FALSE) -> Dermatology | O9: =VLOOKUP(L9,$CL$1:$CU$11,6,FALSE) -> 5 | P9: =VLOOKUP(L9,$CL$1:$CU$11,7,FALSE) -> Westside | Q9: =VLOOKUP(L9,$CL$1:$CU$11,8,FALSE) -> Clinic | CL9: D008 | CM9: Linda | CN9: Brown | CO9: Dermatology | CP9: 9069162601 | CQ9: 5 | CR9: Westside | CS9: Clinic | CT9: dr.linda.brown@hospital.com | CU9: =CM9&" "&CN9 -> Linda Brown | CX9: P008 | CY9: David | CZ9: Davis | DA9: F | DB9: 27946 | DC9: 7090558393 | DD9: 456 Oak Ave | DE9: 44341 | DF9: WellnessCorp | DG9: INS545101 | DH9: david.davis@mail.com | DI9: =CY9&" "&CZ9 -> David Davis
A10: A122 | B10: 45118 | C10: 0.60416667 | D10: Therapy | E10: Cancelled | F10: P012 | G10: =VLOOKUP(F10,$CX$1:$DI$51,12,FALSE) -> Laura Davis | H10: =VLOOKUP(F10,$CX$1:$DI$51,4,FALSE) -> F | I10: =VLOOKUP(F10,$CX$1:$DI$51,5,FALSE) -> 33580 | J10: =DATEDIF(I10,TODAY(),"Y") -> 34 | K10: =_xlfn.IFS(J10<=18,"0-18 Group",J10<=30,"19-30 Group",J10<=45,"31-45 Group",J10<=60,"46-60 Group",J10>60,"60+ ") -> 31-45 Group | L10: D008 | M10: =VLOOKUP(L10,$CL$1:$CU$11,10,FALSE) -> Linda Brown | N10: =VLOOKUP(L10,$CL$1:$CU$11,4,FALSE) -> Dermatology | O10: =VLOOKUP(L10,$CL$1:$CU$11,6,FALSE) -> 5 | P10: =VLOOKUP(L10,$CL$1:$CU$11,7,FALSE) -> Westside | Q10: =VLOOKUP(L10,$CL$1:$CU$11,8,FALSE) -> Clinic | CL10: D009 | CM10: Sarah | CN10: Smith | CO10: Pediatrics | CP10: 7387087517 | CQ10: 26 | CR10: Central | CS10: Hospital | CT10: dr.sarah.smith@hospital.com | CU10: =CM10&" "&CN10 -> Sarah Smith | CX10: P009 | CY10: Laura | CZ10: Davis | DA10: M | DB10: 26278 | DC10: 7060324619 | DD10: 321 Maple Dr | DE10: 44822 | DF10: PulseSecure | DG10: INS136631 | DH10: laura.davis@mail.com | DI10: =CY10&" "&CZ10 -> Laura Davis
A11: A124 | B11: 45001 | C11: 0.71875 | D11: Emergency | E11: Cancelled | F11: P013 | G11: =VLOOKUP(F11,$CX$1:$DI$51,12,FALSE) -> Laura Johnson | H11: =VLOOKUP(F11,$CX$1:$DI$51,4,FALSE) -> F | I11: =VLOOKUP(F11,$CX$1:$DI$51,5,FALSE) -> 32960 | J11: =DATEDIF(I11,TODAY(),"Y") -> 36 | K11: =_xlfn.IFS(J11<=18,"0-18 Group",J11<=30,"19-30 Group",J11<=45,"31-45 Group",J11<=60,"46-60 Group",J11>60,"60+ ") -> 31-45 Group | L11: D008 | M11: =VLOOKUP(L11,$CL$1:$CU$11,10,FALSE) -> Linda Brown | N11: =VLOOKUP(L11,$CL$1:$CU$11,4,FALSE) -> Dermatology | O11: =VLOOKUP(L11,$CL$1:$CU$11,6,FALSE) -> 5 | P11: =VLOOKUP(L11,$CL$1:$CU$11,7,FALSE) -> Westside | Q11: =VLOOKUP(L11,$CL$1:$CU$11,8,FALSE) -> Clinic | CL11: D010 | CM11: Linda | CN11: Wilson | CO11: Oncology | CP11: 6176383634 | CQ11: 21 | CR11: Eastside | CS11: Clinic | CT11: dr.linda.wilson@hospital.com | CU11: =CM11&" "&CN11 -> Linda Wilson | CX11: P010 | CY11: Michael | CZ11: Taylor | DA11: M | DB11: 37177 | DC11: 7081396733 | DD11: 123 Elm St | DE11: 44797 | DF11: WellnessCorp | DG11: INS866577 | DH11: michael.taylor@mail.com | DI11: =CY11&" "&CZ11 -> Michael Taylor
A12: A156 | B12: 45252 | C12: 0.60416667 | D12: Therapy | E12: Completed | F12: P021 | G12: =VLOOKUP(F12,$CX$1:$DI$51,12,FALSE) -> Michael Wilson | H12: =VLOOKUP(F12,$CX$1:$DI$51,4,FALSE) -> M | I12: =VLOOKUP(F12,$CX$1:$DI$51,5,FALSE) -> 37316 | J12: =DATEDIF(I12,TODAY(),"Y") -> 24 | K12: =_xlfn.IFS(J12<=18,"0-18 Group",J12<=30,"19-30 Group",J12<=45,"31-45 Group",J12<=60,"46-60 Group",J12>60,"60+ ") -> 19-30 Group | L12: D008 | M12: =VLOOKUP(L12,$CL$1:$CU$11,10,FALSE) -> Linda Brown | N12: =VLOOKUP(L12,$CL$1:$CU$11,4,FALSE) -> Dermatology | O12: =VLOOKUP(L12,$CL$1:$CU$11,6,FALSE) -> 5 | P12: =VLOOKUP(L12,$CL$1:$CU$11,7,FALSE) -> Westside | Q12: =VLOOKUP(L12,$CL$1:$CU$11,8,FALSE) -> Clinic | CX12: P011 | CY12: Emily | CZ12: Jones | DA12: F | DB12: 24445 | DC12: 8990604070 | DD12: 789 Pine Rd | DE12: 44831 | DF12: MedCare Plus | DG12: INS172991 | DH12: emily.jones@mail.com | DI12: =CY12&" "&CZ12 -> Emily Jones
A13: A164 | B13: 45135 | C13: 0.71875 | D13: Therapy | E13: Cancelled | F13: P014 | G13: =VLOOKUP(F13,$CX$1:$DI$51,12,FALSE) -> Alex Taylor | H13: =VLOOKUP(F13,$CX$1:$DI$51,4,FALSE) -> M | I13: =VLOOKUP(F13,$CX$1:$DI$51,5,FALSE) -> 24895 | J13: =DATEDIF(I13,TODAY(),"Y") -> 58 | K13: =_xlfn.IFS(J13<=18,"0-18 Group",J13<=30,"19-30 Group",J13<=45,"31-45 Group",J13<=60,"46-60 Group",J13>60,"60+ ") -> 46-60 Group | L13: D008 | M13: =VLOOKUP(L13,$CL$1:$CU$11,10,FALSE) -> Linda Brown | N13: =VLOOKUP(L13,$CL$1:$CU$11,4,FALSE) -> Dermatology | O13: =VLOOKUP(L13,$CL$1:$CU$11,6,FALSE) -> 5 | P13: =VLOOKUP(L13,$CL$1:$CU$11,7,FALSE) -> Westside | Q13: =VLOOKUP(L13,$CL$1:$CU$11,8,FALSE) -> Clinic | CX13: P012 | CY13: Laura | CZ13: Davis | DA13: F | DB13: 33580 | DC13: 8135666049 | DD13: 321 Maple Dr | DE13: 45043 | DF13: MedCare Plus | DG13: INS104014 | DH13: laura.davis@mail.com | DI13: =CY13&" "&CZ13 -> Laura Davis
A14: A169 | B14: 45131 | C14: 0.69791667 | D14: Follow-up | E14: Cancelled | F14: P029 | G14: =VLOOKUP(F14,$CX$1:$DI$51,12,FALSE) -> David Smith | H14: =VLOOKUP(F14,$CX$1:$DI$51,4,FALSE) -> M | I14: =VLOOKUP(F14,$CX$1:$DI$51,5,FALSE) -> 38487 | J14: =DATEDIF(I14,TODAY(),"Y") -> 21 | K14: =_xlfn.IFS(J14<=18,"0-18 Group",J14<=30,"19-30 Group",J14<=45,"31-45 Group",J14<=60,"46-60 Group",J14>60,"60+ ") -> 19-30 Group | L14: D008 | M14: =VLOOKUP(L14,$CL$1:$CU$11,10,FALSE) -> Linda Brown | N14: =VLOOKUP(L14,$CL$1:$CU$11,4,FALSE) -> Dermatology | O14: =VLOOKUP(L14,$CL$1:$CU$11,6,FALSE) -> 5 | P14: =VLOOKUP(L14,$CL$1:$CU$11,7,FALSE) -> Westside | Q14: =VLOOKUP(L14,$CL$1:$CU$11,8,FALSE) -> Clinic | CX14: P013 | CY14: Laura | CZ14: Johnson | DA14: F | DB14: 32960 | DC14: 9059178882 | DD14: 321 Maple Dr | DE14: 44553 | DF14: WellnessCorp | DG14: INS373237 | DH14: laura.johnson@mail.com | DI14: =CY14&" "&CZ14 -> Laura Johnson
A15: A180 | B15: 44933 | C15: 0.45833333 | D15: Consultation | E15: Cancelled | F15: P007 | G15: =VLOOKUP(F15,$CX$1:$DI$51,12,FALSE) -> Alex Johnson | H15: =VLOOKUP(F15,$CX$1:$DI$51,4,FALSE) -> F | I15: =VLOOKUP(F15,$CX$1:$DI$51,5,FALSE) -> 32667 | J15: =DATEDIF(I15,TODAY(),"Y") -> 37 | K15: =_xlfn.IFS(J15<=18,"0-18 Group",J15<=30,"19-30 Group",J15<=45,"31-45 Group",J15<=60,"46-60 Group",J15>60,"60+ ") -> 31-45 Group | L15: D008 | M15: =VLOOKUP(L15,$CL$1:$CU$11,10,FALSE) -> Linda Brown | N15: =VLOOKUP(L15,$CL$1:$CU$11,4,FALSE) -> Dermatology | O15: =VLOOKUP(L15,$CL$1:$CU$11,6,FALSE) -> 5 | P15: =VLOOKUP(L15,$CL$1:$CU$11,7,FALSE) -> Westside | Q15: =VLOOKUP(L15,$CL$1:$CU$11,8,FALSE) -> Clinic | CX15: P014 | CY15: Alex | CZ15: Taylor | DA15: M | DB15: 24895 | DC15: 7292262512 | DD15: 789 Pine Rd | DE15: 45272 | DF15: MedCare Plus | DG15: INS118070 | DH15: alex.taylor@mail.com | DI15: =CY15&" "&CZ15 -> Alex Taylor
A16: A182 | B16: 45028 | C16: 0.33333333 | D16: Follow-up | E16: Completed | F16: P013 | G16: =VLOOKUP(F16,$CX$1:$DI$51,12,FALSE) -> Laura Johnson | H16: =VLOOKUP(F16,$CX$1:$DI$51,4,FALSE) -> F | I16: =VLOOKUP(F16,$CX$1:$DI$51,5,FALSE) -> 32960 | J16: =DATEDIF(I16,TODAY(),"Y") -> 36 | K16: =_xlfn.IFS(J16<=18,"0-18 Group",J16<=30,"19-30 Group",J16<=45,"31-45 Group",J16<=60,"46-60 Group",J16>60,"60+ ") -> 31-45 Group | L16: D008 | M16: =VLOOKUP(L16,$CL$1:$CU$11,10,FALSE) -> Linda Brown | N16: =VLOOKUP(L16,$CL$1:$CU$11,4,FALSE) -> Dermatology | O16: =VLOOKUP(L16,$CL$1:$CU$11,6,FALSE) -> 5 | P16: =VLOOKUP(L16,$CL$1:$CU$11,7,FALSE) -> Westside | Q16: =VLOOKUP(L16,$CL$1:$CU$11,8,FALSE) -> Clinic | CX16: P015 | CY16: Sarah | CZ16: Johnson | DA16: M | DB16: 23508 | DC16: 6636028516 | DD16: 321 Maple Dr | DE16: 44464 | DF16: WellnessCorp | DG16: INS922209 | DH16: sarah.johnson@mail.com | DI16: =CY16&" "&CZ16 -> Sarah Johnson
A17: A184 | B17: 44983 | C17: 0.73958333 | D17: Therapy | E17: Completed | F17: P042 | G17: =VLOOKUP(F17,$CX$1:$DI$51,12,FALSE) -> Jane Smith | H17: =VLOOKUP(F17,$CX$1:$DI$51,4,FALSE) -> F | I17: =VLOOKUP(F17,$CX$1:$DI$51,5,FALSE) -> 19958 | J17: =DATEDIF(I17,TODAY(),"Y") -> 72 | K17: =_xlfn.IFS(J17<=18,"0-18 Group",J17<=30,"19-30 Group",J17<=45,"31-45 Group",J17<=60,"46-60 Group",J17>60,"60+ ") -> 60+ | L17: D008 | M17: =VLOOKUP(L17,$CL$1:$CU$11,10,FALSE) -> Linda Brown | N17: =VLOOKUP(L17,$CL$1:$CU$11,4,FALSE) -> Dermatology | O17: =VLOOKUP(L17,$CL$1:$CU$11,6,FALSE) -> 5 | P17: =VLOOKUP(L17,$CL$1:$CU$11,7,FALSE) -> Westside | Q17: =VLOOKUP(L17,$CL$1:$CU$11,8,FALSE) -> Clinic | CX17: P016 | CY17: Michael | CZ17: Taylor | DA17: M | DB17: 36729 | DC17: 7223380592 | DD17: 789 Pine Rd | DE17: 44400 | DF17: PulseSecure | DG17: INS156958 | DH17: michael.taylor@mail.com | DI17: =CY17&" "&CZ17 -> Michael Taylor
A18: A019 | B18: 44963 | C18: 0.64583333 | D18: Checkup | E18: Cancelled | F18: P029 | G18: =VLOOKUP(F18,$CX$1:$DI$51,12,FALSE) -> David Smith | H18: =VLOOKUP(F18,$CX$1:$DI$51,4,FALSE) -> M | I18: =VLOOKUP(F18,$CX$1:$DI$51,5,FALSE) -> 38487 | J18: =DATEDIF(I18,TODAY(),"Y") -> 21 | K18: =_xlfn.IFS(J18<=18,"0-18 Group",J18<=30,"19-30 Group",J18<=45,"31-45 Group",J18<=60,"46-60 Group",J18>60,"60+ ") -> 19-30 Group | L18: D001 | M18: =VLOOKUP(L18,$CL$1:$CU$11,10,FALSE) -> David Taylor | N18: =VLOOKUP(L18,$CL$1:$CU$11,4,FALSE) -> Dermatology | O18: =VLOOKUP(L18,$CL$1:$CU$11,6,FALSE) -> 17 | P18: =VLOOKUP(L18,$CL$1:$CU$11,7,FALSE) -> Westside | Q18: =VLOOKUP(L18,$CL$1:$CU$11,8,FALSE) -> Clinic | CX18: P017 | CY18: Jane | CZ18: Jones | DA18: M | DB18: 33359 | DC18: 6158428240 | DD18: 456 Oak Ave | DE18: 44830 | DF18: WellnessCorp | DG18: INS182074 | DH18: jane.jones@mail.com | DI18: =CY18&" "&CZ18 -> Jane Jones
A19: A022 | B19: 45244 | C19: 0.54166667 | D19: Consultation | E19: No-show | F19: P005 | G19: =VLOOKUP(F19,$CX$1:$DI$51,12,FALSE) -> David Wilson | H19: =VLOOKUP(F19,$CX$1:$DI$51,4,FALSE) -> M | I19: =VLOOKUP(F19,$CX$1:$DI$51,5,FALSE) -> 22090 | J19: =DATEDIF(I19,TODAY(),"Y") -> 66 | K19: =_xlfn.IFS(J19<=18,"0-18 Group",J19<=30,"19-30 Group",J19<=45,"31-45 Group",J19<=60,"46-60 Group",J19>60,"60+ ") -> 60+ | L19: D001 | M19: =VLOOKUP(L19,$CL$1:$CU$11,10,FALSE) -> David Taylor | N19: =VLOOKUP(L19,$CL$1:$CU$11,4,FALSE) -> Dermatology | O19: =VLOOKUP(L19,$CL$1:$CU$11,6,FALSE) -> 17 | P19: =VLOOKUP(L19,$CL$1:$CU$11,7,FALSE) -> Westside | Q19: =VLOOKUP(L19,$CL$1:$CU$11,8,FALSE) -> Clinic | CX19: P018 | CY19: Laura | CZ19: Wilson | DA19: M | DB19: 29122 | DC19: 7145815738 | DD19: 789 Pine Rd | DE19: 44827 | DF19: PulseSecure | DG19: INS635017 | DH19: laura.wilson@mail.com | DI19: =CY19&" "&CZ19 -> Laura Wilson
A20: A025 | B20: 44982 | C20: 0.33333333 | D20: Follow-up | E20: No-show | F20: P030 | G20: =VLOOKUP(F20,$CX$1:$DI$51,12,FALSE) -> Emily Moore | H20: =VLOOKUP(F20,$CX$1:$DI$51,4,FALSE) -> M | I20: =VLOOKUP(F20,$CX$1:$DI$51,5,FALSE) -> 23734 | J20: =DATEDIF(I20,TODAY(),"Y") -> 61 | K20: =_xlfn.IFS(J20<=18,"0-18 Group",J20<=30,"19-30 Group",J20<=45,"31-45 Group",J20<=60,"46-60 Group",J20>60,"60+ ") -> 60+ | L20: D001 | M20: =VLOOKUP(L20,$CL$1:$CU$11,10,FALSE) -> David Taylor | N20: =VLOOKUP(L20,$CL$1:$CU$11,4,FALSE) -> Dermatology | O20: =VLOOKUP(L20,$CL$1:$CU$11,6,FALSE) -> 17 | P20: =VLOOKUP(L20,$CL$1:$CU$11,7,FALSE) -> Westside | Q20: =VLOOKUP(L20,$CL$1:$CU$11,8,FALSE) -> Clinic | CX20: P019 | CY20: Sarah | CZ20: Miller | DA20: M | DB20: 27538 | DC20: 8618058864 | DD20: 789 Pine Rd | DE20: 45101 | DF20: WellnessCorp | DG20: INS855073 | DH20: sarah.miller@mail.com | DI20: =CY20&" "&CZ20 -> Sarah Miller
A21: A041 | B21: 44927 | C21: 0.58333333 | D21: Emergency | E21: No-show | F21: P005 | G21: =VLOOKUP(F21,$CX$1:$DI$51,12,FALSE) -> David Wilson | H21: =VLOOKUP(F21,$CX$1:$DI$51,4,FALSE) -> M | I21: =VLOOKUP(F21,$CX$1:$DI$51,5,FALSE) -> 22090 | J21: =DATEDIF(I21,TODAY(),"Y") -> 66 | K21: =_xlfn.IFS(J21<=18,"0-18 Group",J21<=30,"19-30 Group",J21<=45,"31-45 Group",J21<=60,"46-60 Group",J21>60,"60+ ") -> 60+ | L21: D001 | M21: =VLOOKUP(L21,$CL$1:$CU$11,10,FALSE) -> David Taylor | N21: =VLOOKUP(L21,$CL$1:$CU$11,4,FALSE) -> Dermatology | O21: =VLOOKUP(L21,$CL$1:$CU$11,6,FALSE) -> 17 | P21: =VLOOKUP(L21,$CL$1:$CU$11,7,FALSE) -> Westside | Q21: =VLOOKUP(L21,$CL$1:$CU$11,8,FALSE) -> Clinic | CX21: P020 | CY21: Jane | CZ21: Moore | DA21: F | DB21: 37778 | DC21: 8158989953 | DD21: 789 Pine Rd | DE21: 44654 | DF21: MedCare Plus | DG21: INS276089 | DH21: jane.moore@mail.com | DI21: =CY21&" "&CZ21 -> Jane Moore
A22: A042 | B22: 45006 | C22: 0.46875 | D22: Emergency | E22: Scheduled | F22: P036 | G22: =VLOOKUP(F22,$CX$1:$DI$51,12,FALSE) -> Michael Wilson | H22: =VLOOKUP(F22,$CX$1:$DI$51,4,FALSE) -> M | I22: =VLOOKUP(F22,$CX$1:$DI$51,5,FALSE) -> 35790 | J22: =DATEDIF(I22,TODAY(),"Y") -> 28 | K22: =_xlfn.IFS(J22<=18,"0-18 Group",J22<=30,"19-30 Group",J22<=45,"31-45 Group",J22<=60,"46-60 Group",J22>60,"60+ ") -> 19-30 Group | L22: D001 | M22: =VLOOKUP(L22,$CL$1:$CU$11,10,FALSE) -> David Taylor | N22: =VLOOKUP(L22,$CL$1:$CU$11,4,FALSE) -> Dermatology | O22: =VLOOKUP(L22,$CL$1:$CU$11,6,FALSE) -> 17 | P22: =VLOOKUP(L22,$CL$1:$CU$11,7,FALSE) -> Westside | Q22: =VLOOKUP(L22,$CL$1:$CU$11,8,FALSE) -> Clinic | CX22: P021 | CY22: Michael | CZ22: Wilson | DA22: M | DB22: 37316 | DC22: 7765390555 | DD22: 321 Maple Dr | DE22: 44580 | DF22: WellnessCorp | DG22: INS297392 | DH22: michael.wilson@mail.com | DI22: =CY22&" "&CZ22 -> Michael Wilson
A23: A065 | B23: 45040 | C23: 0.65625 | D23: Emergency | E23: Cancelled | F23: P033 | G23: =VLOOKUP(F23,$CX$1:$DI$51,12,FALSE) -> Michael Wilson | H23: =VLOOKUP(F23,$CX$1:$DI$51,4,FALSE) -> F | I23: =VLOOKUP(F23,$CX$1:$DI$51,5,FALSE) -> 25605 | J23: =DATEDIF(I23,TODAY(),"Y") -> 56 | K23: =_xlfn.IFS(J23<=18,"0-18 Group",J23<=30,"19-30 Group",J23<=45,"31-45 Group",J23<=60,"46-60 Group",J23>60,"60+ ") -> 46-60 Group | L23: D001 | M23: =VLOOKUP(L23,$CL$1:$CU$11,10,FALSE) -> David Taylor | N23: =VLOOKUP(L23,$CL$1:$CU$11,4,FALSE) -> Dermatology | O23: =VLOOKUP(L23,$CL$1:$CU$11,6,FALSE) -> 17 | P23: =VLOOKUP(L23,$CL$1:$CU$11,7,FALSE) -> Westside | Q23: =VLOOKUP(L23,$CL$1:$CU$11,8,FALSE) -> Clinic | CX23: P022 | CY23: John | CZ23: Brown | DA23: M | DB23: 20219 | DC23: 6221099573 | DD23: 321 Maple Dr | DE23: 44327 | DF23: MedCare Plus | DG23: INS258823 | DH23: john.brown@mail.com | DI23: =CY23&" "&CZ23 -> John Brown
... A51: A073 | B51: 45284 | C51: 0.625 | D51: Follow-up | E51: Completed | F51: P040 | G51: =VLOOKUP(F51,$CX$1:$DI$51,12,FALSE) -> Emily Williams | H51: =VLOOKUP(F51,$CX$1:$DI$51,4,FALSE) -> M | I51: =VLOOKUP(F51,$CX$1:$DI$51,5,FALSE) -> 26449 | J51: =DATEDIF(I51,TODAY(),"Y") -> 54 | K51: =_xlfn.IFS(J51<=18,"0-18 Group",J51<=30,"19-30 Group",J51<=45,"31-45 Group",J51<=60,"46-60 Group",J51>60,"60+ ") -> 46-60 Group | L51: D003 | M51: =VLOOKUP(L51,$CL$1:$CU$11,10,FALSE) -> Jane Smith | N51: =VLOOKUP(L51,$CL$1:$CU$11,4,FALSE) -> Pediatrics | O51: =VLOOKUP(L51,$CL$1:$CU$11,6,FALSE) -> 19 | P51: =VLOOKUP(L51,$CL$1:$CU$11,7,FALSE) -> Eastside | Q51: =VLOOKUP(L51,$CL$1:$CU$11,8,FALSE) -> Clinic | CX51: P050 | CY51: Laura | CZ51: Wilson | DA51: M | DB51: 34330 | DC51: 8301134730 | DD51: 321 Maple Dr | DE51: 45044 | DF51: WellnessCorp | DG51: INS712210 | DH51: laura.wilson@mail.com | DI51: =CY51&" "&CZ51 -> Laura Wilson
A52: A096 | B52: 45114 | C52: 0.625 | D52: Consultation | E52: Completed | F52: P004 | G52: =VLOOKUP(F52,$CX$1:$DI$51,12,FALSE) -> Michael Johnson | H52: =VLOOKUP(F52,$CX$1:$DI$51,4,FALSE) -> F | I52: =VLOOKUP(F52,$CX$1:$DI$51,5,FALSE) -> 29637 | J52: =DATEDIF(I52,TODAY(),"Y") -> 45 | K52: =_xlfn.IFS(J52<=18,"0-18 Group",J52<=30,"19-30 Group",J52<=45,"31-45 Group",J52<=60,"46-60 Group",J52>60,"60+ ") -> 31-45 Group | L52: D003 | M52: =VLOOKUP(L52,$CL$1:$CU$11,10,FALSE) -> Jane Smith | N52: =VLOOKUP(L52,$CL$1:$CU$11,4,FALSE) -> Pediatrics | O52: =VLOOKUP(L52,$CL$1:$CU$11,6,FALSE) -> 19 | P52: =VLOOKUP(L52,$CL$1:$CU$11,7,FALSE) -> Eastside | Q52: =VLOOKUP(L52,$CL$1:$CU$11,8,FALSE) -> Clinic
A53: A105 | B53: 45152 | C53: 0.66666667 | D53: Checkup | E53: No-show | F53: P010 | G53: =VLOOKUP(F53,$CX$1:$DI$51,12,FALSE) -> Michael Taylor | H53: =VLOOKUP(F53,$CX$1:$DI$51,4,FALSE) -> M | I53: =VLOOKUP(F53,$CX$1:$DI$51,5,FALSE) -> 37177 | J53: =DATEDIF(I53,TODAY(),"Y") -> 24 | K53: =_xlfn.IFS(J53<=18,"0-18 Group",J53<=30,"19-30 Group",J53<=45,"31-45 Group",J53<=60,"46-60 Group",J53>60,"60+ ") -> 19-30 Group | L53: D003 | M53: =VLOOKUP(L53,$CL$1:$CU$11,10,FALSE) -> Jane Smith | N53: =VLOOKUP(L53,$CL$1:$CU$11,4,FALSE) -> Pediatrics | O53: =VLOOKUP(L53,$CL$1:$CU$11,6,FALSE) -> 19 | P53: =VLOOKUP(L53,$CL$1:$CU$11,7,FALSE) -> Eastside | Q53: =VLOOKUP(L53,$CL$1:$CU$11,8,FALSE) -> Clinic
A54: A113 | B54: 45254 | C54: 0.64583333 | D54: Consultation | E54: Cancelled | F54: P036 | G54: =VLOOKUP(F54,$CX$1:$DI$51,12,FALSE) -> Michael Wilson | H54: =VLOOKUP(F54,$CX$1:$DI$51,4,FALSE) -> M | I54: =VLOOKUP(F54,$CX$1:$DI$51,5,FALSE) -> 35790 | J54: =DATEDIF(I54,TODAY(),"Y") -> 28 | K54: =_xlfn.IFS(J54<=18,"0-18 Group",J54<=30,"19-30 Group",J54<=45,"31-45 Group",J54<=60,"46-60 Group",J54>60,"60+ ") -> 19-30 Group | L54: D003 | M54: =VLOOKUP(L54,$CL$1:$CU$11,10,FALSE) -> Jane Smith | N54: =VLOOKUP(L54,$CL$1:$CU$11,4,FALSE) -> Pediatrics | O54: =VLOOKUP(L54,$CL$1:$CU$11,6,FALSE) -> 19 | P54: =VLOOKUP(L54,$CL$1:$CU$11,7,FALSE) -> Eastside | Q54: =VLOOKUP(L54,$CL$1:$CU$11,8,FALSE) -> Clinic
A55: A118 | B55: 45147 | C55: 0.34375 | D55: Consultation | E55: Scheduled | F55: P024 | G55: =VLOOKUP(F55,$CX$1:$DI$51,12,FALSE) -> Sarah Brown | H55: =VLOOKUP(F55,$CX$1:$DI$51,4,FALSE) -> F | I55: =VLOOKUP(F55,$CX$1:$DI$51,5,FALSE) -> 33546 | J55: =DATEDIF(I55,TODAY(),"Y") -> 34 | K55: =_xlfn.IFS(J55<=18,"0-18 Group",J55<=30,"19-30 Group",J55<=45,"31-45 Group",J55<=60,"46-60 Group",J55>60,"60+ ") -> 31-45 Group | L55: D003 | M55: =VLOOKUP(L55,$CL$1:$CU$11,10,FALSE) -> Jane Smith | N55: =VLOOKUP(L55,$CL$1:$CU$11,4,FALSE) -> Pediatrics | O55: =VLOOKUP(L55,$CL$1:$CU$11,6,FALSE) -> 19 | P55: =VLOOKUP(L55,$CL$1:$CU$11,7,FALSE) -> Eastside | Q55: =VLOOKUP(L55,$CL$1:$CU$11,8,FALSE) -> Clinic
A56: A131 | B56: 45057 | C56: 0.6875 | D56: Therapy | E56: No-show | F56: P049 | G56: =VLOOKUP(F56,$CX$1:$DI$51,12,FALSE) -> David Moore | H56: =VLOOKUP(F56,$CX$1:$DI$51,4,FALSE) -> M | I56: =VLOOKUP(F56,$CX$1:$DI$51,5,FALSE) -> 26629 | J56: =DATEDIF(I56,TODAY(),"Y") -> 53 | K56: =_xlfn.IFS(J56<=18,"0-18 Group",J56<=30,"19-30 Group",J56<=45,"31-45 Group",J56<=60,"46-60 Group",J56>60,"60+ ") -> 46-60 Group | L56: D003 | M56: =VLOOKUP(L56,$CL$1:$CU$11,10,FALSE) -> Jane Smith | N56: =VLOOKUP(L56,$CL$1:$CU$11,4,FALSE) -> Pediatrics | O56: =VLOOKUP(L56,$CL$1:$CU$11,6,FALSE) -> 19 | P56: =VLOOKUP(L56,$CL$1:$CU$11,7,FALSE) -> Eastside | Q56: =VLOOKUP(L56,$CL$1:$CU$11,8,FALSE) -> Clinic
A57: A142 | B57: 45231 | C57: 0.48958333 | D57: Therapy | E57: No-show | F57: P019 | G57: =VLOOKUP(F57,$CX$1:$DI$51,12,FALSE) -> Sarah Miller | H57: =VLOOKUP(F57,$CX$1:$DI$51,4,FALSE) -> M | I57: =VLOOKUP(F57,$CX$1:$DI$51,5,FALSE) -> 27538 | J57: =DATEDIF(I57,TODAY(),"Y") -> 51 | K57: =_xlfn.IFS(J57<=18,"0-18 Group",J57<=30,"19-30 Group",J57<=45,"31-45 Group",J57<=60,"46-60 Group",J57>60,"60+ ") -> 46-60 Group | L57: D003 | M57: =VLOOKUP(L57,$CL$1:$CU$11,10,FALSE) -> Jane Smith | N57: =VLOOKUP(L57,$CL$1:$CU$11,4,FALSE) -> Pediatrics | O57: =VLOOKUP(L57,$CL$1:$CU$11,6,FALSE) -> 19 | P57: =VLOOKUP(L57,$CL$1:$CU$11,7,FALSE) -> Eastside | Q57: =VLOOKUP(L57,$CL$1:$CU$11,8,FALSE) -> Clinic
A58: A150 | B58: 45154 | C58: 0.44791667 | D58: Therapy | E58: Completed | F58: P047 | G58: =VLOOKUP(F58,$CX$1:$DI$51,12,FALSE) -> Jane Moore | H58: =VLOOKUP(F58,$CX$1:$DI$51,4,FALSE) -> M | I58: =VLOOKUP(F58,$CX$1:$DI$51,5,FALSE) -> 35046 | J58: =DATEDIF(I58,TODAY(),"Y") -> 30 | K58: =_xlfn.IFS(J58<=18,"0-18 Group",J58<=30,"19-30 Group",J58<=45,"31-45 Group",J58<=60,"46-60 Group",J58>60,"60+ ") -> 19-30 Group | L58: D003 | M58: =VLOOKUP(L58,$CL$1:$CU$11,10,FALSE) -> Jane Smith | N58: =VLOOKUP(L58,$CL$1:$CU$11,4,FALSE) -> Pediatrics | O58: =VLOOKUP(L58,$CL$1:$CU$11,6,FALSE) -> 19 | P58: =VLOOKUP(L58,$CL$1:$CU$11,7,FALSE) -> Eastside | Q58: =VLOOKUP(L58,$CL$1:$CU$11,8,FALSE) -> Clinic
A59: A159 | B59: 45024 | C59: 0.67708333 | D59: Emergency | E59: No-show | F59: P016 | G59: =VLOOKUP(F59,$CX$1:$DI$51,12,FALSE) -> Michael Taylor | H59: =VLOOKUP(F59,$CX$1:$DI$51,4,FALSE) -> M | I59: =VLOOKUP(F59,$CX$1:$DI$51,5,FALSE) -> 36729 | J59: =DATEDIF(I59,TODAY(),"Y") -> 26 | K59: =_xlfn.IFS(J59<=18,"0-18 Group",J59<=30,"19-30 Group",J59<=45,"31-45 Group",J59<=60,"46-60 Group",J59>60,"60+ ") -> 19-30 Group | L59: D003 | M59: =VLOOKUP(L59,$CL$1:$CU$11,10,FALSE) -> Jane Smith | N59: =VLOOKUP(L59,$CL$1:$CU$11,4,FALSE) -> Pediatrics | O59: =VLOOKUP(L59,$CL$1:$CU$11,6,FALSE) -> 19 | P59: =VLOOKUP(L59,$CL$1:$CU$11,7,FALSE) -> Eastside | Q59: =VLOOKUP(L59,$CL$1:$CU$11,8,FALSE) -> Clinic
A60: A175 | B60: 45221 | C60: 0.70833333 | D60: Consultation | E60: Cancelled | F60: P009 | G60: =VLOOKUP(F60,$CX$1:$DI$51,12,FALSE) -> Laura Davis | H60: =VLOOKUP(F60,$CX$1:$DI$51,4,FALSE) -> M | I60: =VLOOKUP(F60,$CX$1:$DI$51,5,FALSE) -> 26278 | J60: =DATEDIF(I60,TODAY(),"Y") -> 54 | K60: =_xlfn.IFS(J60<=18,"0-18 Group",J60<=30,"19-30 Group",J60<=45,"31-45 Group",J60<=60,"46-60 Group",J60>60,"60+ ") -> 46-60 Group | L60: D003 | M60: =VLOOKUP(L60,$CL$1:$CU$11,10,FALSE) -> Jane Smith | N60: =VLOOKUP(L60,$CL$1:$CU$11,4,FALSE) -> Pediatrics | O60: =VLOOKUP(L60,$CL$1:$CU$11,6,FALSE) -> 19 | P60: =VLOOKUP(L60,$CL$1:$CU$11,7,FALSE) -> Eastside | Q60: =VLOOKUP(L60,$CL$1:$CU$11,8,FALSE) -> Clinic
A61: A186 | B61: 45012 | C61: 0.71875 | D61: Follow-up | E61: No-show | F61: P050 | G61: =VLOOKUP(F61,$CX$1:$DI$51,12,FALSE) -> Laura Wilson | H61: =VLOOKUP(F61,$CX$1:$DI$51,4,FALSE) -> M | I61: =VLOOKUP(F61,$CX$1:$DI$51,5,FALSE) -> 34330 | J61: =DATEDIF(I61,TODAY(),"Y") -> 32 | K61: =_xlfn.IFS(J61<=18,"0-18 Group",J61<=30,"19-30 Group",J61<=45,"31-45 Group",J61<=60,"46-60 Group",J61>60,"60+ ") -> 31-45 Group | L61: D003 | M61: =VLOOKUP(L61,$CL$1:$CU$11,10,FALSE) -> Jane Smith | N61: =VLOOKUP(L61,$CL$1:$CU$11,4,FALSE) -> Pediatrics | O61: =VLOOKUP(L61,$CL$1:$CU$11,6,FALSE) -> 19 | P61: =VLOOKUP(L61,$CL$1:$CU$11,7,FALSE) -> Eastside | Q61: =VLOOKUP(L61,$CL$1:$CU$11,8,FALSE) -> Clinic
A62: A187 | B62: 44970 | C62: 0.52083333 | D62: Consultation | E62: Scheduled | F62: P027 | G62: =VLOOKUP(F62,$CX$1:$DI$51,12,FALSE) -> Linda Moore | H62: =VLOOKUP(F62,$CX$1:$DI$51,4,FALSE) -> F | I62: =VLOOKUP(F62,$CX$1:$DI$51,5,FALSE) -> 35975 | J62: =DATEDIF(I62,TODAY(),"Y") -> 28 | K62: =_xlfn.IFS(J62<=18,"0-18 Group",J62<=30,"19-30 Group",J62<=45,"31-45 Group",J62<=60,"46-60 Group",J62>60,"60+ ") -> 19-30 Group | L62: D003 | M62: =VLOOKUP(L62,$CL$1:$CU$11,10,FALSE) -> Jane Smith | N62: =VLOOKUP(L62,$CL$1:$CU$11,4,FALSE) -> Pediatrics | O62: =VLOOKUP(L62,$CL$1:$CU$11,6,FALSE) -> 19 | P62: =VLOOKUP(L62,$CL$1:$CU$11,7,FALSE) -> Eastside | Q62: =VLOOKUP(L62,$CL$1:$CU$11,8,FALSE) -> Clinic
A63: A190 | B63: 45246 | C63: 0.63541667 | D63: Checkup | E63: Scheduled | F63: P029 | G63: =VLOOKUP(F63,$CX$1:$DI$51,12,FALSE) -> David Smith | H63: =VLOOKUP(F63,$CX$1:$DI$51,4,FALSE) -> M | I63: =VLOOKUP(F63,$CX$1:$DI$51,5,FALSE) -> 38487 | J63: =DATEDIF(I63,TODAY(),"Y") -> 21 | K63: =_xlfn.IFS(J63<=18,"0-18 Group",J63<=30,"19-30 Group",J63<=45,"31-45 Group",J63<=60,"46-60 Group",J63>60,"60+ ") -> 19-30 Group | L63: D003 | M63: =VLOOKUP(L63,$CL$1:$CU$11,10,FALSE) -> Jane Smith | N63: =VLOOKUP(L63,$CL$1:$CU$11,4,FALSE) -> Pediatrics | O63: =VLOOKUP(L63,$CL$1:$CU$11,6,FALSE) -> 19 | P63: =VLOOKUP(L63,$CL$1:$CU$11,7,FALSE) -> Eastside | Q63: =VLOOKUP(L63,$CL$1:$CU$11,8,FALSE) -> Clinic
... A201: A183 | B201: 44960 | C201: 0.67708333 | D201: Checkup | E201: Completed | F201: P040 | G201: =VLOOKUP(F201,$CX$1:$DI$51,12,FALSE) -> Emily Williams | H201: =VLOOKUP(F201,$CX$1:$DI$51,4,FALSE) -> M | I201: =VLOOKUP(F201,$CX$1:$DI$51,5,FALSE) -> 26449 | J201: =DATEDIF(I201,TODAY(),"Y") -> 54 | K201: =_xlfn.IFS(J201<=18,"0-18 Group",J201<=30,"19-30 Group",J201<=45,"31-45 Group",J201<=60,"46-60 Group",J201>60,"60+ ") -> 46-60 Group | L201: D004 | M201: =VLOOKUP(L201,$CL$1:$CU$11,10,FALSE) -> David Jones | N201: =VLOOKUP(L201,$CL$1:$CU$11,4,FALSE) -> Pediatrics | O201: =VLOOKUP(L201,$CL$1:$CU$11,6,FALSE) -> 28 | P201: =VLOOKUP(L201,$CL$1:$CU$11,7,FALSE) -> Central | Q201: =VLOOKUP(L201,$CL$1:$CU$11,8,FALSE) -> Hospital

Sheet change log
C3: No Missing values
C4: No duplicates
C5: No Extra Spaces
C6: Changed Appointment time datatype 'General' into 'Time'
C7: Changed Appointment date datatype 'General' into 'Short Date'
C8: ADD Patient name,Gender,Date of Birth ,Age from Patient table using Vlookup Function
C9: Create a new column named Age Group
C10: Distinct the hospital_branch into 2 columns and add this columns
C11: ADD Doctor name,Specialaization,years of experience ,Hospital &branch name from doctor table using Vlookup Function

Sheet Analysis
C4: Total No Of Appointments | D4: 200
C6: Total No of Appointments in each Status | D6: Appointment Status | E6: Count
D7: Scheduled | E7: 51
D8: No-show | E8: 52
D9: Completed | E9: 46
D10: Cancelled | E10: 51
C12: Percentage of Appointments in each status | D12: Appointment Status | E12: Count
D13: Scheduled | E13: 0.255
D14: No-show | E14: 0.26
D15: Completed | E15: 0.23
D16: Cancelled | E16: 0.255
C18: Average no of appointments handled by each doctor | D18: Doctor name | E18: Number of appointments | F18: Average no of appointments
D19: David Taylor | E19: 25 | F19: 0.125
D20: Jane Davis | E20: 21 | F20: 0.105
D21: Jane Smith | E21: 22 | F21: 0.11
D22: David Jones | E22: 14 | F22: 0.07
D23: Sarah Taylor | E23: 29 | F23: 0.145
D24: Alex Davis | E24: 24 | F24: 0.12
D25: Robert Davis | E25: 13 | F25: 0.065
D26: Linda Brown | E26: 16 | F26: 0.08
D27: Sarah Smith | E27: 17 | F27: 0.085
D28: Linda Wilson | E28: 19 | F28: 0.095
C30: department doctors have less experience | D30: Dermatology
C32: the total No of doctors | D32: 10

Sheet DASHBOARD
G2: HOSPITAL MANAGEMENT DASHBOARD | U2: JAN 2023 - DEC 2023

Sheet Insights
B2: Questions
B4: 1 | C4: What is the Total No of Completed Appointments?
B5: 2 | C5: What is the total no of completed ,cancelled,Scheduled and No-show appointments?
B6: 3 | C6: What percentage of appointments were completed,cancelled,scheduled and No-show?
B7: 4 | C7: What is the total No of doctors ?
B8: 5 | C8: What is the average no of appointments handled by each doctor?
B9: 6 | C9: which department doctors have less experience?
B12: 7 | C12: which doctors have the highest number of appointments in monthly?
B13: 8 | C13: What is the monthly trend of Appointments?
B14: 9 | C14: What are the most common reasons For patient Visits?
B15: 10 | C15: Which doctor Specializations receive the most Appointments?
B16: 11 | C16: How are Appointments distributed by patient demographics?
B17: 12 | C17: Which hospital branch has the highest no of appointments
B20: Findings
C21: 1.APPOINTMENTS WORKLOAD
C22: The hospital recorded 200 appointments
C23: Dr.Sarah Taylor Handled the highest no of Appointments with 29
C24: The average workload was 20 appointments per doctor
C25: The analysis show that appointment workload is not evenly distributed among doctors,with Dr.Sarah Taylor handling the highest number of appointments
C27: 2.APPOINTMENT STATUS
C28: Completed:46
C29: Scheduled:51
C30: Cancelled:51
C31: No-Show:52
C32: No-Show Appointments are the highest category,slightly higher than Scheduled and Cancelled Appointments
C33: The hospital has a realtively high number of no-show appointments,indicating that patient attendance coulde be an area for improvement
... C67: The patient data shows a higher proportion of male patients compared with female patients
B70: Recommendations
B71: 1.Reduce No-Show Appointments
C72: Send SMS/Whatsapp reminders before Appointments
C73: Allow patients to confirm or reschedule appointments
C74: Maintain a list of frequently missed appointments
B76: 2.Manage Doctor Workload
C77: Monitor doctor wise Appointment workload
C78: Distribute appointments more evenly where possible
C79: Add appointment slots during high demand periods
B81: 3.Improve High Demand Specializations
C82: Provide sufficient doctors and appointment slots for high demand specializations
C83: increase resources during busy periods
C84: monitor demand regularly
...

Sheet dctr&dptmnt
A3: Row Labels
A4: Alex Davis
A5: Pediatrics
A6: David Jones
A7: Pediatrics
A8: David Taylor
A9: Dermatology
A10: Jane Davis
A11: Pediatrics
A12: Jane Smith
A13: Pediatrics
A14: Linda Brown
... A24: Grand Total

Sheet 1.appointment doctor
A3: Row Labels | B3: Count of appointment_id
A4: Alex Davis | B4: 24
A5: David Jones | B5: 14
A6: David Taylor | B6: 25
A7: Jane Davis | B7: 21
A8: Jane Smith | B8: 22
A9: Linda Brown | B9: 16
A10: Linda Wilson | B10: 19
A11: Robert Davis | B11: 13
A12: Sarah Smith | B12: 17
A13: Sarah Taylor | B13: 29
A14: Grand Total | B14: 200

Sheet 3.reason for visit
A3: Row Labels | B3: Count of appointment_id
A4: Checkup | B4: 45
A5: Consultation | B5: 43
A6: Emergency | B6: 29
A7: Follow-up | B7: 41
A8: Therapy | B8: 42
A9: Grand Total | B9: 200
B12: =GETPIVOTDATA("appointment_id",$A$3) -> 200

Sheet 2.monthly apntmnt 
A3: Row Labels | B3: Count of appointment_id
A4: Jan | B4: 20
A5: Feb | B5: 14
A6: Mar | B6: 19
A7: Apr | B7: 25
A8: May | B8: 19
A9: Jun | B9: 18
A10: Jul | B10: 16
A11: Aug | B11: 15
A12: Sep | B12: 11
A13: Oct | B13: 14
A14: Nov | B14: 17
A15: Dec | B15: 12
A16: Grand Total | B16: 200

Sheet 4.specialization
A3: Row Labels | B3: Count of appointment_id
A4: Dermatology | B4: 70
A5: Oncology | B5: 32
A6: Pediatrics | B6: 98
A7: Grand Total | B7: 200

Sheet 6.gender
A3: Row Labels | B3: Count of appointment_id
A4: F | B4: 70
A5: M | B5: 130
A6: Grand Total | B6: 200

Sheet 5.hsptlbranch
A3: Row Labels | B3: Count of appointment_id
A4: Central | B4: 84
A5: Eastside | B5: 62
A6: Westside | B6: 54
A7: Grand Total | B7: 200

Sheet 7.Status
A3: Row Labels | B3: Count of appointment_id
A4: Cancelled | B4: 51
A5: Completed | B5: 46
A6: No-show | B6: 52
A7: Scheduled | B7: 51
A8: Grand Total | B8: 200

Sheet KPI cards
A1: total appointments | B1: =COUNTA('cleaned data'!$A$2:$A$201) -> 200
A2: total patients | B2: =COUNTA('cleaned data'!$CX$2:$CX$51) -> 50
A3: total doctors | B3: =COUNTA('cleaned data'!$CL$2:$CL$11) -> 10
A4: completed appointmnets | B4: =COUNTIF('cleaned data'!$E$2:$E$201,"Completed") -> 46
A5: cancelled appointmnets | B5: =COUNTIF('cleaned data'!$E$2:$E$201,"Cancelled") -> 51
A6: completion rate | B6: =B4/B1 -> 0.23
